[ERROR] 2025-05-19 05:53:59,931 django.request (248): Internal Server Error: /project/
Traceback (most recent call last):
  File "/home/codespace/.local/lib/python3.12/site-packages/django/core/handlers/exception.py", line 55, in inner
    response = get_response(request)
               ^^^^^^^^^^^^^^^^^^^^^
  File "/home/codespace/.local/lib/python3.12/site-packages/django/core/handlers/base.py", line 197, in _get_response
    response = wrapped_callback(request, *callback_args, **callback_kwargs)
               ^^^^^^^^^^^^^^^^^^^^^^^^^^^^^^^^^^^^^^^^^^^^^^^^^^^^^^^^^^^^
  File "/workspaces/aynal-haque/core/views.py", line 75, in project_view
    projects = Project.objects.all().order_by('-created_at')
               ^^^^^^^
NameError: name 'Project' is not defined
[ERROR] 2025-05-19 05:53:59,934 django.server (213): "GET /project/ HTTP/1.1" 500 76192
[ERROR] 2025-05-19 06:57:41,847 django.request (248): Internal Server Error: /chatbot/
Traceback (most recent call last):
  File "/home/codespace/.local/lib/python3.12/site-packages/django/core/handlers/exception.py", line 55, in inner
    response = get_response(request)
               ^^^^^^^^^^^^^^^^^^^^^
  File "/home/codespace/.local/lib/python3.12/site-packages/django/core/handlers/base.py", line 220, in _get_response
    response = response.render()
               ^^^^^^^^^^^^^^^^^
  File "/home/codespace/.local/lib/python3.12/site-packages/django/template/response.py", line 114, in render
    self.content = self.rendered_content
                   ^^^^^^^^^^^^^^^^^^^^^
  File "/home/codespace/.local/lib/python3.12/site-packages/django/template/response.py", line 90, in rendered_content
    template = self.resolve_template(self.template_name)
               ^^^^^^^^^^^^^^^^^^^^^^^^^^^^^^^^^^^^^^^^^
  File "/home/codespace/.local/lib/python3.12/site-packages/django/template/response.py", line 72, in resolve_template
    return select_template(template, using=self.using)
           ^^^^^^^^^^^^^^^^^^^^^^^^^^^^^^^^^^^^^^^^^^^
  File "/home/codespace/.local/lib/python3.12/site-packages/django/template/loader.py", line 47, in select_template
    raise TemplateDoesNotExist(", ".join(template_name_list), chain=chain)
django.template.exceptions.TemplateDoesNotExist: chatbot/chat.html
[ERROR] 2025-05-19 06:57:41,849 django.server (213): "GET /chatbot/ HTTP/1.1" 500 91252
[ERROR] 2025-05-19 06:58:22,268 django.request (248): Internal Server Error: /chatbot/ask/
[ERROR] 2025-05-19 06:58:22,268 django.server (213): "POST /chatbot/ask/ HTTP/1.1" 500 488
[ERROR] 2025-05-19 06:58:30,695 django.request (248): Internal Server Error: /chatbot/ask/
[ERROR] 2025-05-19 06:58:30,696 django.server (213): "POST /chatbot/ask/ HTTP/1.1" 500 488
[ERROR] 2025-05-19 07:03:44,175 django.request (248): Internal Server Error: /chatbot/
Traceback (most recent call last):
  File "/home/codespace/.local/lib/python3.12/site-packages/django/template/backends/django.py", line 107, in render
    return self.template.render(context)
           ^^^^^^^^^^^^^^^^^^^^^^^^^^^^^
  File "/home/codespace/.local/lib/python3.12/site-packages/django/template/base.py", line 171, in render
    return self._render(context)
           ^^^^^^^^^^^^^^^^^^^^^
  File "/home/codespace/.local/lib/python3.12/site-packages/django/template/base.py", line 163, in _render
    return self.nodelist.render(context)
           ^^^^^^^^^^^^^^^^^^^^^^^^^^^^^
  File "/home/codespace/.local/lib/python3.12/site-packages/django/template/base.py", line 1016, in render
    return SafeString("".join([node.render_annotated(context) for node in self]))
                               ^^^^^^^^^^^^^^^^^^^^^^^^^^^^^^
  File "/home/codespace/.local/lib/python3.12/site-packages/django/template/base.py", line 977, in render_annotated
    return self.render(context)
           ^^^^^^^^^^^^^^^^^^^^
  File "/home/codespace/.local/lib/python3.12/site-packages/django/template/loader_tags.py", line 159, in render
    return compiled_parent._render(context)
           ^^^^^^^^^^^^^^^^^^^^^^^^^^^^^^^^
  File "/home/codespace/.local/lib/python3.12/site-packages/django/template/base.py", line 163, in _render
    return self.nodelist.render(context)
           ^^^^^^^^^^^^^^^^^^^^^^^^^^^^^
  File "/home/codespace/.local/lib/python3.12/site-packages/django/template/base.py", line 1016, in render
    return SafeString("".join([node.render_annotated(context) for node in self]))
                               ^^^^^^^^^^^^^^^^^^^^^^^^^^^^^^
  File "/home/codespace/.local/lib/python3.12/site-packages/django/template/base.py", line 977, in render_annotated
    return self.render(context)
           ^^^^^^^^^^^^^^^^^^^^
  File "/home/codespace/.local/lib/python3.12/site-packages/django/template/loader_tags.py", line 199, in render
    template = context.template.engine.select_template(template_name)
               ^^^^^^^^^^^^^^^^^^^^^^^^^^^^^^^^^^^^^^^^^^^^^^^^^^^^^^
  File "/home/codespace/.local/lib/python3.12/site-packages/django/template/engine.py", line 214, in select_template
    raise TemplateDoesNotExist(", ".join(not_found))
django.template.exceptions.TemplateDoesNotExist: chatbot/sidebar.html

The above exception was the direct cause of the following exception:

Traceback (most recent call last):
  File "/home/codespace/.local/lib/python3.12/site-packages/django/core/handlers/exception.py", line 55, in inner
    response = get_response(request)
               ^^^^^^^^^^^^^^^^^^^^^
  File "/home/codespace/.local/lib/python3.12/site-packages/django/core/handlers/base.py", line 220, in _get_response
    response = response.render()
               ^^^^^^^^^^^^^^^^^
  File "/home/codespace/.local/lib/python3.12/site-packages/django/template/response.py", line 114, in render
    self.content = self.rendered_content
                   ^^^^^^^^^^^^^^^^^^^^^
  File "/home/codespace/.local/lib/python3.12/site-packages/django/template/response.py", line 92, in rendered_content
    return template.render(context, self._request)
           ^^^^^^^^^^^^^^^^^^^^^^^^^^^^^^^^^^^^^^^
  File "/home/codespace/.local/lib/python3.12/site-packages/django/template/backends/django.py", line 109, in render
    reraise(exc, self.backend)
  File "/home/codespace/.local/lib/python3.12/site-packages/django/template/backends/django.py", line 130, in reraise
    raise new from exc
django.template.exceptions.TemplateDoesNotExist: chatbot/sidebar.html
[ERROR] 2025-05-19 07:03:44,177 django.server (213): "GET /chatbot/ HTTP/1.1" 500 143867
[ERROR] 2025-05-19 07:04:14,242 django.request (248): Internal Server Error: /chatbot/ask/
[ERROR] 2025-05-19 07:04:14,242 django.server (213): "POST /chatbot/ask/ HTTP/1.1" 500 488
[ERROR] 2025-05-19 07:06:12,336 django.request (248): Internal Server Error: /chatbot/ask/
[ERROR] 2025-05-19 07:06:12,336 django.server (213): "POST /chatbot/ask/ HTTP/1.1" 500 488
